Workbook

Sheet الدرجات
A1: code | B1: name | C1: s1:w | D1: s1:o | E1: s1:r | F1: s2:w | G1: s2:o | H1: s2:r | I1: s3:w | J1: s3:o | K1: s3:r | L1: s4:w | M1: s4:o | N1: s4:r | O1: s5:w | P1: s5:o | Q1: s5:r | R1: s6:w | S1: s6:o | T1: s6:r | U1: s7:w | V1: s7:o | W1: s7:r
A2: الكود | B2: الاسم | C2: العقيدة المسيحية تحريري | D2: العقيدة المسيحية شفوي | E2: العقيدة المسيحية إعادة التحريري | F2: العهد القديم تحريري | G2: العهد القديم شفوي | H2: العهد القديم إعادة التحريري | I2: العهد الجديد تحريري | J2: العهد الجديد شفوي | K2: العهد الجديد إعادة التحريري | L2: الطقوس والألحان تحريري | M2: الطقوس والألحان شفوي | N2: الطقوس والألحان إعادة التحريري | O2: تاريخ الكنيسة تحريري | P2: تاريخ الكنيسة شفوي | Q2: تاريخ الكنيسة إعادة التحريري | R2: الرعاية والافتقاد تحريري | S2: الرعاية والافتقاد شفوي | T2: الرعاية والافتقاد إعادة التحريري | U2: اللاهوت المقارن تحريري | V2: اللاهوت المقارن شفوي | W2: اللاهوت المقارن إعادة التحريري
A3: 1001 | B3: مينا جرجس
A4: 1002 | B4: مريم سمير
A5: 1003 | B5: بيتر عادل
A6: 1004 | B6: مارتينا ناجي
A7: 1005 | B7: كيرلس فادي
A8: 1006 | B8: إيريني صبحي
A9: 1007 | B9: مارك ماهر
A10: 1008 | B10: فيرينا نبيل

Sheet النتائج
A1: النتائج المحسوبة (للقراءة فقط، لا تُستورد)
A2: ناجح | C2: ناجح برأفة | E2: إعادة مطلوبة | G2: راسب | I2: قيد المراجعة | K2: لم تكتمل
A3: =COUNTIF($L$5:$L$60,"ناجح") -> 0 | C3: =COUNTIF($L$5:$L$60,"ناجح برأفة") -> 0 | E3: =COUNTIF($L$5:$L$60,"إعادة مطلوبة") -> 0 | G3: =COUNTIF($L$5:$L$60,"راسب") -> 0 | I3: =COUNTIF($L$5:$L$60,"قيد المراجعة") -> 0 | K3: =COUNTIF($L$5:$L$60,"لم تكتمل") -> 56
A4: الكود | B4: الاسم | C4: المادة | D4: تحريري | E4: شفوي | F4: إعادة | G4: التحريري المعتمد | H4: المجموع قبل الرأفة | I4: رأفة | J4: المجموع | K4: النسبة | L4: النتيجة
A5: 1001 | B5: =INDEX(الدرجات!$B$3:$B$10,MATCH($A5,الدرجات!$A$3:$A$10,0)) -> مينا جرجس | C5: =الإعدادات!$B$19 -> العقيدة المسيحية | D5: =IF(INDEX(الدرجات!$C$3:$W$10,MATCH($A5,الدرجات!$A$3:$A$10,0),1)="","",INDEX(الدرجات!$C$3:$W$10,MATCH($A5,الدرجات!$A$3:$A$10,0),1)) | E5: =IF(INDEX(الدرجات!$C$3:$W$10,MATCH($A5,الدرجات!$A$3:$A$10,0),2)="","",INDEX(الدرجات!$C$3:$W$10,MATCH($A5,الدرجات!$A$3:$A$10,0),2)) | F5: =IF(INDEX(الدرجات!$C$3:$W$10,MATCH($A5,الدرجات!$A$3:$A$10,0),3)="","",INDEX(الدرجات!$C$3:$W$10,MATCH($A5,الدرجات!$A$3:$A$10,0),3)) | G5: =IF(OR(D5="محجوب",E5="محجوب",F5="محجوب"),"",IF(ISNUMBER(F5),IF(الإعدادات!$B$6="سقف",MIN(F5,الإعدادات!$B$10),F5),IF(ISNUMBER(D5),D5,""))) | H5: =IF(OR(D5="محجوب",E5="محجوب",F5="محجوب"),"",IF(AND(ISNUMBER(G5),ISNUMBER(E5)),G5+E5,"")) | I5: =IF(H5="","",IF(H5>=الإعدادات!$B$8,0,IF(ROUND(الإعدادات!$B$8-H5,2)<=الإعدادات!$B$9,ROUND(الإعدادات!$B$8-H5,2),0))) | J5: =IF(H5="","",H5+I5) | K5: =IF(J5="","",J5/الإعدادات!$B$7) | L5: =IF(OR(D5="محجوب",E5="محجوب",F5="محجوب"),"قيد المراجعة",IF(J5="",IF(OR(D5="غائب",D5="بعذر"),"إعادة مطلوبة","لم تكتمل"),IF(ROUND(J5,2)>=ROUND(الإعدادات!$B$8,2),IF(I5>0,"ناجح برأفة","ناجح"),IF(ISNUMBER(F5),"راسب","إعادة مطلوبة")))) -> لم تكتمل
A6: 1001 | B6: =INDEX(الدرجات!$B$3:$B$10,MATCH($A6,الدرجات!$A$3:$A$10,0)) -> مينا جرجس | C6: =الإعدادات!$B$20 -> العهد القديم | D6: =IF(INDEX(الدرجات!$C$3:$W$10,MATCH($A6,الدرجات!$A$3:$A$10,0),4)="","",INDEX(الدرجات!$C$3:$W$10,MATCH($A6,الدرجات!$A$3:$A$10,0),4)) | E6: =IF(INDEX(الدرجات!$C$3:$W$10,MATCH($A6,الدرجات!$A$3:$A$10,0),5)="","",INDEX(الدرجات!$C$3:$W$10,MATCH($A6,الدرجات!$A$3:$A$10,0),5)) | F6: =IF(INDEX(الدرجات!$C$3:$W$10,MATCH($A6,الدرجات!$A$3:$A$10,0),6)="","",INDEX(الدرجات!$C$3:$W$10,MATCH($A6,الدرجات!$A$3:$A$10,0),6)) | G6: =IF(OR(D6="محجوب",E6="محجوب",F6="محجوب"),"",IF(ISNUMBER(F6),IF(الإعدادات!$B$6="سقف",MIN(F6,الإعدادات!$B$10),F6),IF(ISNUMBER(D6),D6,""))) | H6: =IF(OR(D6="محجوب",E6="محجوب",F6="محجوب"),"",IF(AND(ISNUMBER(G6),ISNUMBER(E6)),G6+E6,"")) | I6: =IF(H6="","",IF(H6>=الإعدادات!$B$8,0,IF(ROUND(الإعدادات!$B$8-H6,2)<=الإعدادات!$B$9,ROUND(الإعدادات!$B$8-H6,2),0))) | J6: =IF(H6="","",H6+I6) | K6: =IF(J6="","",J6/الإعدادات!$B$7) | L6: =IF(OR(D6="محجوب",E6="محجوب",F6="محجوب"),"قيد المراجعة",IF(J6="",IF(OR(D6="غائب",D6="بعذر"),"إعادة مطلوبة","لم تكتمل"),IF(ROUND(J6,2)>=ROUND(الإعدادات!$B$8,2),IF(I6>0,"ناجح برأفة","ناجح"),IF(ISNUMBER(F6),"راسب","إعادة مطلوبة")))) -> لم تكتمل
A7: 1001 | B7: =INDEX(الدرجات!$B$3:$B$10,MATCH($A7,الدرجات!$A$3:$A$10,0)) -> مينا جرجس | C7: =الإعدادات!$B$21 -> العهد الجديد | D7: =IF(INDEX(الدرجات!$C$3:$W$10,MATCH($A7,الدرجات!$A$3:$A$10,0),7)="","",INDEX(الدرجات!$C$3:$W$10,MATCH($A7,الدرجات!$A$3:$A$10,0),7)) | E7: =IF(INDEX(الدرجات!$C$3:$W$10,MATCH($A7,الدرجات!$A$3:$A$10,0),8)="","",INDEX(الدرجات!$C$3:$W$10,MATCH($A7,الدرجات!$A$3:$A$10,0),8)) | F7: =IF(INDEX(الدرجات!$C$3:$W$10,MATCH($A7,الدرجات!$A$3:$A$10,0),9)="","",INDEX(الدرجات!$C$3:$W$10,MATCH($A7,الدرجات!$A$3:$A$10,0),9)) | G7: =IF(OR(D7="محجوب",E7="محجوب",F7="محجوب"),"",IF(ISNUMBER(F7),IF(الإعدادات!$B$6="سقف",MIN(F7,الإعدادات!$B$10),F7),IF(ISNUMBER(D7),D7,""))) | H7: =IF(OR(D7="محجوب",E7="محجوب",F7="محجوب"),"",IF(AND(ISNUMBER(G7),ISNUMBER(E7)),G7+E7,"")) | I7: =IF(H7="","",IF(H7>=الإعدادات!$B$8,0,IF(ROUND(الإعدادات!$B$8-H7,2)<=الإعدادات!$B$9,ROUND(الإعدادات!$B$8-H7,2),0))) | J7: =IF(H7="","",H7+I7) | K7: =IF(J7="","",J7/الإعدادات!$B$7) | L7: =IF(OR(D7="محجوب",E7="محجوب",F7="محجوب"),"قيد المراجعة",IF(J7="",IF(OR(D7="غائب",D7="بعذر"),"إعادة مطلوبة","لم تكتمل"),IF(ROUND(J7,2)>=ROUND(الإعدادات!$B$8,2),IF(I7>0,"ناجح برأفة","ناجح"),IF(ISNUMBER(F7),"راسب","إعادة مطلوبة")))) -> لم تكتمل
A8: 1001 | B8: =INDEX(الدرجات!$B$3:$B$10,MATCH($A8,الدرجات!$A$3:$A$10,0)) -> مينا جرجس | C8: =الإعدادات!$B$22 -> الطقوس والألحان | D8: =IF(INDEX(الدرجات!$C$3:$W$10,MATCH($A8,الدرجات!$A$3:$A$10,0),10)="","",INDEX(الدرجات!$C$3:$W$10,MATCH($A8,الدرجات!$A$3:$A$10,0),10)) | E8: =IF(INDEX(الدرجات!$C$3:$W$10,MATCH($A8,الدرجات!$A$3:$A$10,0),11)="","",INDEX(الدرجات!$C$3:$W$10,MATCH($A8,الدرجات!$A$3:$A$10,0),11)) | F8: =IF(INDEX(الدرجات!$C$3:$W$10,MATCH($A8,الدرجات!$A$3:$A$10,0),12)="","",INDEX(الدرجات!$C$3:$W$10,MATCH($A8,الدرجات!$A$3:$A$10,0),12)) | G8: =IF(OR(D8="محجوب",E8="محجوب",F8="محجوب"),"",IF(ISNUMBER(F8),IF(الإعدادات!$B$6="سقف",MIN(F8,الإعدادات!$B$10),F8),IF(ISNUMBER(D8),D8,""))) | H8: =IF(OR(D8="محجوب",E8="محجوب",F8="محجوب"),"",IF(AND(ISNUMBER(G8),ISNUMBER(E8)),G8+E8,"")) | I8: =IF(H8="","",IF(H8>=الإعدادات!$B$8,0,IF(ROUND(الإعدادات!$B$8-H8,2)<=الإعدادات!$B$9,ROUND(الإعدادات!$B$8-H8,2),0))) | J8: =IF(H8="","",H8+I8) | K8: =IF(J8="","",J8/الإعدادات!$B$7) | L8: =IF(OR(D8="محجوب",E8="محجوب",F8="محجوب"),"قيد المراجعة",IF(J8="",IF(OR(D8="غائب",D8="بعذر"),"إعادة مطلوبة","لم تكتمل"),IF(ROUND(J8,2)>=ROUND(الإعدادات!$B$8,2),IF(I8>0,"ناجح برأفة","ناجح"),IF(ISNUMBER(F8),"راسب","إعادة مطلوبة")))) -> لم تكتمل
A9: 1001 | B9: =INDEX(الدرجات!$B$3:$B$10,MATCH($A9,الدرجات!$A$3:$A$10,0)) -> مينا جرجس | C9: =الإعدادات!$B$23 -> تاريخ الكنيسة | D9: =IF(INDEX(الدرجات!$C$3:$W$10,MATCH($A9,الدرجات!$A$3:$A$10,0),13)="","",INDEX(الدرجات!$C$3:$W$10,MATCH($A9,الدرجات!$A$3:$A$10,0),13)) | E9: =IF(INDEX(الدرجات!$C$3:$W$10,MATCH($A9,الدرجات!$A$3:$A$10,0),14)="","",INDEX(الدرجات!$C$3:$W$10,MATCH($A9,الدرجات!$A$3:$A$10,0),14)) | F9: =IF(INDEX(الدرجات!$C$3:$W$10,MATCH($A9,الدرجات!$A$3:$A$10,0),15)="","",INDEX(الدرجات!$C$3:$W$10,MATCH($A9,الدرجات!$A$3:$A$10,0),15)) | G9: =IF(OR(D9="محجوب",E9="محجوب",F9="محجوب"),"",IF(ISNUMBER(F9),IF(الإعدادات!$B$6="سقف",MIN(F9,الإعدادات!$B$10),F9),IF(ISNUMBER(D9),D9,""))) | H9: =IF(OR(D9="محجوب",E9="محجوب",F9="محجوب"),"",IF(AND(ISNUMBER(G9),ISNUMBER(E9)),G9+E9,"")) | I9: =IF(H9="","",IF(H9>=الإعدادات!$B$8,0,IF(ROUND(الإعدادات!$B$8-H9,2)<=الإعدادات!$B$9,ROUND(الإعدادات!$B$8-H9,2),0))) | J9: =IF(H9="","",H9+I9) | K9: =IF(J9="","",J9/الإعدادات!$B$7) | L9: =IF(OR(D9="محجوب",E9="محجوب",F9="محجوب"),"قيد المراجعة",IF(J9="",IF(OR(D9="غائب",D9="بعذر"),"إعادة مطلوبة","لم تكتمل"),IF(ROUND(J9,2)>=ROUND(الإعدادات!$B$8,2),IF(I9>0,"ناجح برأفة","ناجح"),IF(ISNUMBER(F9),"راسب","إعادة مطلوبة")))) -> لم تكتمل
A10: 1001 | B10: =INDEX(الدرجات!$B$3:$B$10,MATCH($A10,الدرجات!$A$3:$A$10,0)) -> مينا جرجس | C10: =الإعدادات!$B$24 -> الرعاية والافتقاد | D10: =IF(INDEX(الدرجات!$C$3:$W$10,MATCH($A10,الدرجات!$A$3:$A$10,0),16)="","",INDEX(الدرجات!$C$3:$W$10,MATCH($A10,الدرجات!$A$3:$A$10,0),16)) | E10: =IF(INDEX(الدرجات!$C$3:$W$10,MATCH($A10,الدرجات!$A$3:$A$10,0),17)="","",INDEX(الدرجات!$C$3:$W$10,MATCH($A10,الدرجات!$A$3:$A$10,0),17)) | F10: =IF(INDEX(الدرجات!$C$3:$W$10,MATCH($A10,الدرجات!$A$3:$A$10,0),18)="","",INDEX(الدرجات!$C$3:$W$10,MATCH($A10,الدرجات!$A$3:$A$10,0),18)) | G10: =IF(OR(D10="محجوب",E10="محجوب",F10="محجوب"),"",IF(ISNUMBER(F10),IF(الإعدادات!$B$6="سقف",MIN(F10,الإعدادات!$B$10),F10),IF(ISNUMBER(D10),D10,""))) | H10: =IF(OR(D10="محجوب",E10="محجوب",F10="محجوب"),"",IF(AND(ISNUMBER(G10),ISNUMBER(E10)),G10+E10,"")) | I10: =IF(H10="","",IF(H10>=الإعدادات!$B$8,0,IF(ROUND(الإعدادات!$B$8-H10,2)<=الإعدادات!$B$9,ROUND(الإعدادات!$B$8-H10,2),0))) | J10: =IF(H10="","",H10+I10) | K10: =IF(J10="","",J10/الإعدادات!$B$7) | L10: =IF(OR(D10="محجوب",E10="محجوب",F10="محجوب"),"قيد المراجعة",IF(J10="",IF(OR(D10="غائب",D10="بعذر"),"إعادة مطلوبة","لم تكتمل"),IF(ROUND(J10,2)>=ROUND(الإعدادات!$B$8,2),IF(I10>0,"ناجح برأفة","ناجح"),IF(ISNUMBER(F10),"راسب","إعادة مطلوبة")))) -> لم تكتمل
A11: 1001 | B11: =INDEX(الدرجات!$B$3:$B$10,MATCH($A11,الدرجات!$A$3:$A$10,0)) -> مينا جرجس | C11: =الإعدادات!$B$25 -> اللاهوت المقارن | D11: =IF(INDEX(الدرجات!$C$3:$W$10,MATCH($A11,الدرجات!$A$3:$A$10,0),19)="","",INDEX(الدرجات!$C$3:$W$10,MATCH($A11,الدرجات!$A$3:$A$10,0),19)) | E11: =IF(INDEX(الدرجات!$C$3:$W$10,MATCH($A11,الدرجات!$A$3:$A$10,0),20)="","",INDEX(الدرجات!$C$3:$W$10,MATCH($A11,الدرجات!$A$3:$A$10,0),20)) | F11: =IF(INDEX(الدرجات!$C$3:$W$10,MATCH($A11,الدرجات!$A$3:$A$10,0),21)="","",INDEX(الدرجات!$C$3:$W$10,MATCH($A11,الدرجات!$A$3:$A$10,0),21)) | G11: =IF(OR(D11="محجوب",E11="محجوب",F11="محجوب"),"",IF(ISNUMBER(F11),IF(الإعدادات!$B$6="سقف",MIN(F11,الإعدادات!$B$10),F11),IF(ISNUMBER(D11),D11,""))) | H11: =IF(OR(D11="محجوب",E11="محجوب",F11="محجوب"),"",IF(AND(ISNUMBER(G11),ISNUMBER(E11)),G11+E11,"")) | I11: =IF(H11="","",IF(H11>=الإعدادات!$B$8,0,IF(ROUND(الإعدادات!$B$8-H11,2)<=الإعدادات!$B$9,ROUND(الإعدادات!$B$8-H11,2),0))) | J11: =IF(H11="","",H11+I11) | K11: =IF(J11="","",J11/الإعدادات!$B$7) | L11: =IF(OR(D11="محجوب",E11="محجوب",F11="محجوب"),"قيد المراجعة",IF(J11="",IF(OR(D11="غائب",D11="بعذر"),"إعادة مطلوبة","لم تكتمل"),IF(ROUND(J11,2)>=ROUND(الإعدادات!$B$8,2),IF(I11>0,"ناجح برأفة","ناجح"),IF(ISNUMBER(F11),"راسب","إعادة مطلوبة")))) -> لم تكتمل
A12: 1002 | B12: =INDEX(الدرجات!$B$3:$B$10,MATCH($A12,الدرجات!$A$3:$A$10,0)) -> مريم سمير | C12: =الإعدادات!$B$19 -> العقيدة المسيحية | D12: =IF(INDEX(الدرجات!$C$3:$W$10,MATCH($A12,الدرجات!$A$3:$A$10,0),1)="","",INDEX(الدرجات!$C$3:$W$10,MATCH($A12,الدرجات!$A$3:$A$10,0),1)) | E12: =IF(INDEX(الدرجات!$C$3:$W$10,MATCH($A12,الدرجات!$A$3:$A$10,0),2)="","",INDEX(الدرجات!$C$3:$W$10,MATCH($A12,الدرجات!$A$3:$A$10,0),2)) | F12: =IF(INDEX(الدرجات!$C$3:$W$10,MATCH($A12,الدرجات!$A$3:$A$10,0),3)="","",INDEX(الدرجات!$C$3:$W$10,MATCH($A12,الدرجات!$A$3:$A$10,0),3)) | G12: =IF(OR(D12="محجوب",E12="محجوب",F12="محجوب"),"",IF(ISNUMBER(F12),IF(الإعدادات!$B$6="سقف",MIN(F12,الإعدادات!$B$10),F12),IF(ISNUMBER(D12),D12,""))) | H12: =IF(OR(D12="محجوب",E12="محجوب",F12="محجوب"),"",IF(AND(ISNUMBER(G12),ISNUMBER(E12)),G12+E12,"")) | I12: =IF(H12="","",IF(H12>=الإعدادات!$B$8,0,IF(ROUND(الإعدادات!$B$8-H12,2)<=الإعدادات!$B$9,ROUND(الإعدادات!$B$8-H12,2),0))) | J12: =IF(H12="","",H12+I12) | K12: =IF(J12="","",J12/الإعدادات!$B$7) | L12: =IF(OR(D12="محجوب",E12="محجوب",F12="محجوب"),"قيد المراجعة",IF(J12="",IF(OR(D12="غائب",D12="بعذر"),"إعادة مطلوبة","لم تكتمل"),IF(ROUND(J12,2)>=ROUND(الإعدادات!$B$8,2),IF(I12>0,"ناجح برأفة","ناجح"),IF(ISNUMBER(F12),"راسب","إعادة مطلوبة")))) -> لم تكتمل
A13: 1002 | B13: =INDEX(الدرجات!$B$3:$B$10,MATCH($A13,الدرجات!$A$3:$A$10,0)) -> مريم سمير | C13: =الإعدادات!$B$20 -> العهد القديم | D13: =IF(INDEX(الدرجات!$C$3:$W$10,MATCH($A13,الدرجات!$A$3:$A$10,0),4)="","",INDEX(الدرجات!$C$3:$W$10,MATCH($A13,الدرجات!$A$3:$A$10,0),4)) | E13: =IF(INDEX(الدرجات!$C$3:$W$10,MATCH($A13,الدرجات!$A$3:$A$10,0),5)="","",INDEX(الدرجات!$C$3:$W$10,MATCH($A13,الدرجات!$A$3:$A$10,0),5)) | F13: =IF(INDEX(الدرجات!$C$3:$W$10,MATCH($A13,الدرجات!$A$3:$A$10,0),6)="","",INDEX(الدرجات!$C$3:$W$10,MATCH($A13,الدرجات!$A$3:$A$10,0),6)) | G13: =IF(OR(D13="محجوب",E13="محجوب",F13="محجوب"),"",IF(ISNUMBER(F13),IF(الإعدادات!$B$6="سقف",MIN(F13,الإعدادات!$B$10),F13),IF(ISNUMBER(D13),D13,""))) | H13: =IF(OR(D13="محجوب",E13="محجوب",F13="محجوب"),"",IF(AND(ISNUMBER(G13),ISNUMBER(E13)),G13+E13,"")) | I13: =IF(H13="","",IF(H13>=الإعدادات!$B$8,0,IF(ROUND(الإعدادات!$B$8-H13,2)<=الإعدادات!$B$9,ROUND(الإعدادات!$B$8-H13,2),0))) | J13: =IF(H13="","",H13+I13) | K13: =IF(J13="","",J13/الإعدادات!$B$7) | L13: =IF(OR(D13="محجوب",E13="محجوب",F13="محجوب"),"قيد المراجعة",IF(J13="",IF(OR(D13="غائب",D13="بعذر"),"إعادة مطلوبة","لم تكتمل"),IF(ROUND(J13,2)>=ROUND(الإعدادات!$B$8,2),IF(I13>0,"ناجح برأفة","ناجح"),IF(ISNUMBER(F13),"راسب","إعادة مطلوبة")))) -> لم تكتمل
A14: 1002 | B14: =INDEX(الدرجات!$B$3:$B$10,MATCH($A14,الدرجات!$A$3:$A$10,0)) -> مريم سمير | C14: =الإعدادات!$B$21 -> العهد الجديد | D14: =IF(INDEX(الدرجات!$C$3:$W$10,MATCH($A14,الدرجات!$A$3:$A$10,0),7)="","",INDEX(الدرجات!$C$3:$W$10,MATCH($A14,الدرجات!$A$3:$A$10,0),7)) | E14: =IF(INDEX(الدرجات!$C$3:$W$10,MATCH($A14,الدرجات!$A$3:$A$10,0),8)="","",INDEX(الدرجات!$C$3:$W$10,MATCH($A14,الدرجات!$A$3:$A$10,0),8)) | F14: =IF(INDEX(الدرجات!$C$3:$W$10,MATCH($A14,الدرجات!$A$3:$A$10,0),9)="","",INDEX(الدرجات!$C$3:$W$10,MATCH($A14,الدرجات!$A$3:$A$10,0),9)) | G14: =IF(OR(D14="محجوب",E14="محجوب",F14="محجوب"),"",IF(ISNUMBER(F14),IF(الإعدادات!$B$6="سقف",MIN(F14,الإعدادات!$B$10),F14),IF(ISNUMBER(D14),D14,""))) | H14: =IF(OR(D14="محجوب",E14="محجوب",F14="محجوب"),"",IF(AND(ISNUMBER(G14),ISNUMBER(E14)),G14+E14,"")) | I14: =IF(H14="","",IF(H14>=الإعدادات!$B$8,0,IF(ROUND(الإعدادات!$B$8-H14,2)<=الإعدادات!$B$9,ROUND(الإعدادات!$B$8-H14,2),0))) | J14: =IF(H14="","",H14+I14) | K14: =IF(J14="","",J14/الإعدادات!$B$7) | L14: =IF(OR(D14="محجوب",E14="محجوب",F14="محجوب"),"قيد المراجعة",IF(J14="",IF(OR(D14="غائب",D14="بعذر"),"إعادة مطلوبة","لم تكتمل"),IF(ROUND(J14,2)>=ROUND(الإعدادات!$B$8,2),IF(I14>0,"ناجح برأفة","ناجح"),IF(ISNUMBER(F14),"راسب","إعادة مطلوبة")))) -> لم تكتمل
A15: 1002 | B15: =INDEX(الدرجات!$B$3:$B$10,MATCH($A15,الدرجات!$A$3:$A$10,0)) -> مريم سمير | C15: =الإعدادات!$B$22 -> الطقوس والألحان | D15: =IF(INDEX(الدرجات!$C$3:$W$10,MATCH($A15,الدرجات!$A$3:$A$10,0),10)="","",INDEX(الدرجات!$C$3:$W$10,MATCH($A15,الدرجات!$A$3:$A$10,0),10)) | E15: =IF(INDEX(الدرجات!$C$3:$W$10,MATCH($A15,الدرجات!$A$3:$A$10,0),11)="","",INDEX(الدرجات!$C$3:$W$10,MATCH($A15,الدرجات!$A$3:$A$10,0),11)) | F15: =IF(INDEX(الدرجات!$C$3:$W$10,MATCH($A15,الدرجات!$A$3:$A$10,0),12)="","",INDEX(الدرجات!$C$3:$W$10,MATCH($A15,الدرجات!$A$3:$A$10,0),12)) | G15: =IF(OR(D15="محجوب",E15="محجوب",F15="محجوب"),"",IF(ISNUMBER(F15),IF(الإعدادات!$B$6="سقف",MIN(F15,الإعدادات!$B$10),F15),IF(ISNUMBER(D15),D15,""))) | H15: =IF(OR(D15="محجوب",E15="محجوب",F15="محجوب"),"",IF(AND(ISNUMBER(G15),ISNUMBER(E15)),G15+E15,"")) | I15: =IF(H15="","",IF(H15>=الإعدادات!$B$8,0,IF(ROUND(الإعدادات!$B$8-H15,2)<=الإعدادات!$B$9,ROUND(الإعدادات!$B$8-H15,2),0))) | J15: =IF(H15="","",H15+I15) | K15: =IF(J15="","",J15/الإعدادات!$B$7) | L15: =IF(OR(D15="محجوب",E15="محجوب",F15="محجوب"),"قيد المراجعة",IF(J15="",IF(OR(D15="غائب",D15="بعذر"),"إعادة مطلوبة","لم تكتمل"),IF(ROUND(J15,2)>=ROUND(الإعدادات!$B$8,2),IF(I15>0,"ناجح برأفة","ناجح"),IF(ISNUMBER(F15),"راسب","إعادة مطلوبة")))) -> لم تكتمل
A16: 1002 | B16: =INDEX(الدرجات!$B$3:$B$10,MATCH($A16,الدرجات!$A$3:$A$10,0)) -> مريم سمير | C16: =الإعدادات!$B$23 -> تاريخ الكنيسة | D16: =IF(INDEX(الدرجات!$C$3:$W$10,MATCH($A16,الدرجات!$A$3:$A$10,0),13)="","",INDEX(الدرجات!$C$3:$W$10,MATCH($A16,الدرجات!$A$3:$A$10,0),13)) | E16: =IF(INDEX(الدرجات!$C$3:$W$10,MATCH($A16,الدرجات!$A$3:$A$10,0),14)="","",INDEX(الدرجات!$C$3:$W$10,MATCH($A16,الدرجات!$A$3:$A$10,0),14)) | F16: =IF(INDEX(الدرجات!$C$3:$W$10,MATCH($A16,الدرجات!$A$3:$A$10,0),15)="","",INDEX(الدرجات!$C$3:$W$10,MATCH($A16,الدرجات!$A$3:$A$10,0),15)) | G16: =IF(OR(D16="محجوب",E16="محجوب",F16="محجوب"),"",IF(ISNUMBER(F16),IF(الإعدادات!$B$6="سقف",MIN(F16,الإعدادات!$B$10),F16),IF(ISNUMBER(D16),D16,""))) | H16: =IF(OR(D16="محجوب",E16="محجوب",F16="محجوب"),"",IF(AND(ISNUMBER(G16),ISNUMBER(E16)),G16+E16,"")) | I16: =IF(H16="","",IF(H16>=الإعدادات!$B$8,0,IF(ROUND(الإعدادات!$B$8-H16,2)<=الإعدادات!$B$9,ROUND(الإعدادات!$B$8-H16,2),0))) | J16: =IF(H16="","",H16+I16) | K16: =IF(J16="","",J16/الإعدادات!$B$7) | L16: =IF(OR(D16="محجوب",E16="محجوب",F16="محجوب"),"قيد المراجعة",IF(J16="",IF(OR(D16="غائب",D16="بعذر"),"إعادة مطلوبة","لم تكتمل"),IF(ROUND(J16,2)>=ROUND(الإعدادات!$B$8,2),IF(I16>0,"ناجح برأفة","ناجح"),IF(ISNUMBER(F16),"راسب","إعادة مطلوبة")))) -> لم تكتمل
A17: 1002 | B17: =INDEX(الدرجات!$B$3:$B$10,MATCH($A17,الدرجات!$A$3:$A$10,0)) -> مريم سمير | C17: =الإعدادات!$B$24 -> الرعاية والافتقاد | D17: =IF(INDEX(الدرجات!$C$3:$W$10,MATCH($A17,الدرجات!$A$3:$A$10,0),16)="","",INDEX(الدرجات!$C$3:$W$10,MATCH($A17,الدرجات!$A$3:$A$10,0),16)) | E17: =IF(INDEX(الدرجات!$C$3:$W$10,MATCH($A17,الدرجات!$A$3:$A$10,0),17)="","",INDEX(الدرجات!$C$3:$W$10,MATCH($A17,الدرجات!$A$3:$A$10,0),17)) | F17: =IF(INDEX(الدرجات!$C$3:$W$10,MATCH($A17,الدرجات!$A$3:$A$10,0),18)="","",INDEX(الدرجات!$C$3:$W$10,MATCH($A17,الدرجات!$A$3:$A$10,0),18)) | G17: =IF(OR(D17="محجوب",E17="محجوب",F17="محجوب"),"",IF(ISNUMBER(F17),IF(الإعدادات!$B$6="سقف",MIN(F17,الإعدادات!$B$10),F17),IF(ISNUMBER(D17),D17,""))) | H17: =IF(OR(D17="محجوب",E17="محجوب",F17="محجوب"),"",IF(AND(ISNUMBER(G17),ISNUMBER(E17)),G17+E17,"")) | I17: =IF(H17="","",IF(H17>=الإعدادات!$B$8,0,IF(ROUND(الإعدادات!$B$8-H17,2)<=الإعدادات!$B$9,ROUND(الإعدادات!$B$8-H17,2),0))) | J17: =IF(H17="","",H17+I17) | K17: =IF(J17="","",J17/الإعدادات!$B$7) | L17: =IF(OR(D17="محجوب",E17="محجوب",F17="محجوب"),"قيد المراجعة",IF(J17="",IF(OR(D17="غائب",D17="بعذر"),"إعادة مطلوبة","لم تكتمل"),IF(ROUND(J17,2)>=ROUND(الإعدادات!$B$8,2),IF(I17>0,"ناجح برأفة","ناجح"),IF(ISNUMBER(F17),"راسب","إعادة مطلوبة")))) -> لم تكتمل
A18: 1002 | B18: =INDEX(الدرجات!$B$3:$B$10,MATCH($A18,الدرجات!$A$3:$A$10,0)) -> مريم سمير | C18: =الإعدادات!$B$25 -> اللاهوت المقارن | D18: =IF(INDEX(الدرجات!$C$3:$W$10,MATCH($A18,الدرجات!$A$3:$A$10,0),19)="","",INDEX(الدرجات!$C$3:$W$10,MATCH($A18,الدرجات!$A$3:$A$10,0),19)) | E18: =IF(INDEX(الدرجات!$C$3:$W$10,MATCH($A18,الدرجات!$A$3:$A$10,0),20)="","",INDEX(الدرجات!$C$3:$W$10,MATCH($A18,الدرجات!$A$3:$A$10,0),20)) | F18: =IF(INDEX(الدرجات!$C$3:$W$10,MATCH($A18,الدرجات!$A$3:$A$10,0),21)="","",INDEX(الدرجات!$C$3:$W$10,MATCH($A18,الدرجات!$A$3:$A$10,0),21)) | G18: =IF(OR(D18="محجوب",E18="محجوب",F18="محجوب"),"",IF(ISNUMBER(F18),IF(الإعدادات!$B$6="سقف",MIN(F18,الإعدادات!$B$10),F18),IF(ISNUMBER(D18),D18,""))) | H18: =IF(OR(D18="محجوب",E18="محجوب",F18="محجوب"),"",IF(AND(ISNUMBER(G18),ISNUMBER(E18)),G18+E18,"")) | I18: =IF(H18="","",IF(H18>=الإعدادات!$B$8,0,IF(ROUND(الإعدادات!$B$8-H18,2)<=الإعدادات!$B$9,ROUND(الإعدادات!$B$8-H18,2),0))) | J18: =IF(H18="","",H18+I18) | K18: =IF(J18="","",J18/الإعدادات!$B$7) | L18: =IF(OR(D18="محجوب",E18="محجوب",F18="محجوب"),"قيد المراجعة",IF(J18="",IF(OR(D18="غائب",D18="بعذر"),"إعادة مطلوبة","لم تكتمل"),IF(ROUND(J18,2)>=ROUND(الإعدادات!$B$8,2),IF(I18>0,"ناجح برأفة","ناجح"),IF(ISNUMBER(F18),"راسب","إعادة مطلوبة")))) -> لم تكتمل
A19: 1003 | B19: =INDEX(الدرجات!$B$3:$B$10,MATCH($A19,الدرجات!$A$3:$A$10,0)) -> بيتر عادل | C19: =الإعدادات!$B$19 -> العقيدة المسيحية | D19: =IF(INDEX(الدرجات!$C$3:$W$10,MATCH($A19,الدرجات!$A$3:$A$10,0),1)="","",INDEX(الدرجات!$C$3:$W$10,MATCH($A19,الدرجات!$A$3:$A$10,0),1)) | E19: =IF(INDEX(الدرجات!$C$3:$W$10,MATCH($A19,الدرجات!$A$3:$A$10,0),2)="","",INDEX(الدرجات!$C$3:$W$10,MATCH($A19,الدرجات!$A$3:$A$10,0),2)) | F19: =IF(INDEX(الدرجات!$C$3:$W$10,MATCH($A19,الدرجات!$A$3:$A$10,0),3)="","",INDEX(الدرجات!$C$3:$W$10,MATCH($A19,الدرجات!$A$3:$A$10,0),3)) | G19: =IF(OR(D19="محجوب",E19="محجوب",F19="محجوب"),"",IF(ISNUMBER(F19),IF(الإعدادات!$B$6="سقف",MIN(F19,الإعدادات!$B$10),F19),IF(ISNUMBER(D19),D19,""))) | H19: =IF(OR(D19="محجوب",E19="محجوب",F19="محجوب"),"",IF(AND(ISNUMBER(G19),ISNUMBER(E19)),G19+E19,"")) | I19: =IF(H19="","",IF(H19>=الإعدادات!$B$8,0,IF(ROUND(الإعدادات!$B$8-H19,2)<=الإعدادات!$B$9,ROUND(الإعدادات!$B$8-H19,2),0))) | J19: =IF(H19="","",H19+I19) | K19: =IF(J19="","",J19/الإعدادات!$B$7) | L19: =IF(OR(D19="محجوب",E19="محجوب",F19="محجوب"),"قيد المراجعة",IF(J19="",IF(OR(D19="غائب",D19="بعذر"),"إعادة مطلوبة","لم تكتمل"),IF(ROUND(J19,2)>=ROUND(الإعدادات!$B$8,2),IF(I19>0,"ناجح برأفة","ناجح"),IF(ISNUMBER(F19),"راسب","إعادة مطلوبة")))) -> لم تكتمل
A20: 1003 | B20: =INDEX(الدرجات!$B$3:$B$10,MATCH($A20,الدرجات!$A$3:$A$10,0)) -> بيتر عادل | C20: =الإعدادات!$B$20 -> العهد القديم | D20: =IF(INDEX(الدرجات!$C$3:$W$10,MATCH($A20,الدرجات!$A$3:$A$10,0),4)="","",INDEX(الدرجات!$C$3:$W$10,MATCH($A20,الدرجات!$A$3:$A$10,0),4)) | E20: =IF(INDEX(الدرجات!$C$3:$W$10,MATCH($A20,الدرجات!$A$3:$A$10,0),5)="","",INDEX(الدرجات!$C$3:$W$10,MATCH($A20,الدرجات!$A$3:$A$10,0),5)) | F20: =IF(INDEX(الدرجات!$C$3:$W$10,MATCH($A20,الدرجات!$A$3:$A$10,0),6)="","",INDEX(الدرجات!$C$3:$W$10,MATCH($A20,الدرجات!$A$3:$A$10,0),6)) | G20: =IF(OR(D20="محجوب",E20="محجوب",F20="محجوب"),"",IF(ISNUMBER(F20),IF(الإعدادات!$B$6="سقف",MIN(F20,الإعدادات!$B$10),F20),IF(ISNUMBER(D20),D20,""))) | H20: =IF(OR(D20="محجوب",E20="محجوب",F20="محجوب"),"",IF(AND(ISNUMBER(G20),ISNUMBER(E20)),G20+E20,"")) | I20: =IF(H20="","",IF(H20>=الإعدادات!$B$8,0,IF(ROUND(الإعدادات!$B$8-H20,2)<=الإعدادات!$B$9,ROUND(الإعدادات!$B$8-H20,2),0))) | J20: =IF(H20="","",H20+I20) | K20: =IF(J20="","",J20/الإعدادات!$B$7) | L20: =IF(OR(D20="محجوب",E20="محجوب",F20="محجوب"),"قيد المراجعة",IF(J20="",IF(OR(D20="غائب",D20="بعذر"),"إعادة مطلوبة","لم تكتمل"),IF(ROUND(J20,2)>=ROUND(الإعدادات!$B$8,2),IF(I20>0,"ناجح برأفة","ناجح"),IF(ISNUMBER(F20),"راسب","إعادة مطلوبة")))) -> لم تكتمل
A21: 1003 | B21: =INDEX(الدرجات!$B$3:$B$10,MATCH($A21,الدرجات!$A$3:$A$10,0)) -> بيتر عادل | C21: =الإعدادات!$B$21 -> العهد الجديد | D21: =IF(INDEX(الدرجات!$C$3:$W$10,MATCH($A21,الدرجات!$A$3:$A$10,0),7)="","",INDEX(الدرجات!$C$3:$W$10,MATCH($A21,الدرجات!$A$3:$A$10,0),7)) | E21: =IF(INDEX(الدرجات!$C$3:$W$10,MATCH($A21,الدرجات!$A$3:$A$10,0),8)="","",INDEX(الدرجات!$C$3:$W$10,MATCH($A21,الدرجات!$A$3:$A$10,0),8)) | F21: =IF(INDEX(الدرجات!$C$3:$W$10,MATCH($A21,الدرجات!$A$3:$A$10,0),9)="","",INDEX(الدرجات!$C$3:$W$10,MATCH($A21,الدرجات!$A$3:$A$10,0),9)) | G21: =IF(OR(D21="محجوب",E21="محجوب",F21="محجوب"),"",IF(ISNUMBER(F21),IF(الإعدادات!$B$6="سقف",MIN(F21,الإعدادات!$B$10),F21),IF(ISNUMBER(D21),D21,""))) | H21: =IF(OR(D21="محجوب",E21="محجوب",F21="محجوب"),"",IF(AND(ISNUMBER(G21),ISNUMBER(E21)),G21+E21,"")) | I21: =IF(H21="","",IF(H21>=الإعدادات!$B$8,0,IF(ROUND(الإعدادات!$B$8-H21,2)<=الإعدادات!$B$9,ROUND(الإعدادات!$B$8-H21,2),0))) | J21: =IF(H21="","",H21+I21) | K21: =IF(J21="","",J21/الإعدادات!$B$7) | L21: =IF(OR(D21="محجوب",E21="محجوب",F21="محجوب"),"قيد المراجعة",IF(J21="",IF(OR(D21="غائب",D21="بعذر"),"إعادة مطلوبة","لم تكتمل"),IF(ROUND(J21,2)>=ROUND(الإعدادات!$B$8,2),IF(I21>0,"ناجح برأفة","ناجح"),IF(ISNUMBER(F21),"راسب","إعادة مطلوبة")))) -> لم تكتمل
A22: 1003 | B22: =INDEX(الدرجات!$B$3:$B$10,MATCH($A22,الدرجات!$A$3:$A$10,0)) -> بيتر عادل | C22: =الإعدادات!$B$22 -> الطقوس والألحان | D22: =IF(INDEX(الدرجات!$C$3:$W$10,MATCH($A22,الدرجات!$A$3:$A$10,0),10)="","",INDEX(الدرجات!$C$3:$W$10,MATCH($A22,الدرجات!$A$3:$A$10,0),10)) | E22: =IF(INDEX(الدرجات!$C$3:$W$10,MATCH($A22,الدرجات!$A$3:$A$10,0),11)="","",INDEX(الدرجات!$C$3:$W$10,MATCH($A22,الدرجات!$A$3:$A$10,0),11)) | F22: =IF(INDEX(الدرجات!$C$3:$W$10,MATCH($A22,الدرجات!$A$3:$A$10,0),12)="","",INDEX(الدرجات!$C$3:$W$10,MATCH($A22,الدرجات!$A$3:$A$10,0),12)) | G22: =IF(OR(D22="محجوب",E22="محجوب",F22="محجوب"),"",IF(ISNUMBER(F22),IF(الإعدادات!$B$6="سقف",MIN(F22,الإعدادات!$B$10),F22),IF(ISNUMBER(D22),D22,""))) | H22: =IF(OR(D22="محجوب",E22="محجوب",F22="محجوب"),"",IF(AND(ISNUMBER(G22),ISNUMBER(E22)),G22+E22,"")) | I22: =IF(H22="","",IF(H22>=الإعدادات!$B$8,0,IF(ROUND(الإعدادات!$B$8-H22,2)<=الإعدادات!$B$9,ROUND(الإعدادات!$B$8-H22,2),0))) | J22: =IF(H22="","",H22+I22) | K22: =IF(J22="","",J22/الإعدادات!$B$7) | L22: =IF(OR(D22="محجوب",E22="محجوب",F22="محجوب"),"قيد المراجعة",IF(J22="",IF(OR(D22="غائب",D22="بعذر"),"إعادة مطلوبة","لم تكتمل"),IF(ROUND(J22,2)>=ROUND(الإعدادات!$B$8,2),IF(I22>0,"ناجح برأفة","ناجح"),IF(ISNUMBER(F22),"راسب","إعادة مطلوبة")))) -> لم تكتمل
A23: 1003 | B23: =INDEX(الدرجات!$B$3:$B$10,MATCH($A23,الدرجات!$A$3:$A$10,0)) -> بيتر عادل | C23: =الإعدادات!$B$23 -> تاريخ الكنيسة | D23: =IF(INDEX(الدرجات!$C$3:$W$10,MATCH($A23,الدرجات!$A$3:$A$10,0),13)="","",INDEX(الدرجات!$C$3:$W$10,MATCH($A23,الدرجات!$A$3:$A$10,0),13)) | E23: =IF(INDEX(الدرجات!$C$3:$W$10,MATCH($A23,الدرجات!$A$3:$A$10,0),14)="","",INDEX(الدرجات!$C$3:$W$10,MATCH($A23,الدرجات!$A$3:$A$10,0),14)) | F23: =IF(INDEX(الدرجات!$C$3:$W$10,MATCH($A23,الدرجات!$A$3:$A$10,0),15)="","",INDEX(الدرجات!$C$3:$W$10,MATCH($A23,الدرجات!$A$3:$A$10,0),15)) | G23: =IF(OR(D23="محجوب",E23="محجوب",F23="محجوب"),"",IF(ISNUMBER(F23),IF(الإعدادات!$B$6="سقف",MIN(F23,الإعدادات!$B$10),F23),IF(ISNUMBER(D23),D23,""))) | H23: =IF(OR(D23="محجوب",E23="محجوب",F23="محجوب"),"",IF(AND(ISNUMBER(G23),ISNUMBER(E23)),G23+E23,"")) | I23: =IF(H23="","",IF(H23>=الإعدادات!$B$8,0,IF(ROUND(الإعدادات!$B$8-H23,2)<=الإعدادات!$B$9,ROUND(الإعدادات!$B$8-H23,2),0))) | J23: =IF(H23="","",H23+I23) | K23: =IF(J23="","",J23/الإعدادات!$B$7) | L23: =IF(OR(D23="محجوب",E23="محجوب",F23="محجوب"),"قيد المراجعة",IF(J23="",IF(OR(D23="غائب",D23="بعذر"),"إعادة مطلوبة","لم تكتمل"),IF(ROUND(J23,2)>=ROUND(الإعدادات!$B$8,2),IF(I23>0,"ناجح برأفة","ناجح"),IF(ISNUMBER(F23),"راسب","إعادة مطلوبة")))) -> لم تكتمل
A24: 1003 | B24: =INDEX(الدرجات!$B$3:$B$10,MATCH($A24,الدرجات!$A$3:$A$10,0)) -> بيتر عادل | C24: =الإعدادات!$B$24 -> الرعاية والافتقاد | D24: =IF(INDEX(الدرجات!$C$3:$W$10,MATCH($A24,الدرجات!$A$3:$A$10,0),16)="","",INDEX(الدرجات!$C$3:$W$10,MATCH($A24,الدرجات!$A$3:$A$10,0),16)) | E24: =IF(INDEX(الدرجات!$C$3:$W$10,MATCH($A24,الدرجات!$A$3:$A$10,0),17)="","",INDEX(الدرجات!$C$3:$W$10,MATCH($A24,الدرجات!$A$3:$A$10,0),17)) | F24: =IF(INDEX(الدرجات!$C$3:$W$10,MATCH($A24,الدرجات!$A$3:$A$10,0),18)="","",INDEX(الدرجات!$C$3:$W$10,MATCH($A24,الدرجات!$A$3:$A$10,0),18)) | G24: =IF(OR(D24="محجوب",E24="محجوب",F24="محجوب"),"",IF(ISNUMBER(F24),IF(الإعدادات!$B$6="سقف",MIN(F24,الإعدادات!$B$10),F24),IF(ISNUMBER(D24),D24,""))) | H24: =IF(OR(D24="محجوب",E24="محجوب",F24="محجوب"),"",IF(AND(ISNUMBER(G24),ISNUMBER(E24)),G24+E24,"")) | I24: =IF(H24="","",IF(H24>=الإعدادات!$B$8,0,IF(ROUND(الإعدادات!$B$8-H24,2)<=الإعدادات!$B$9,ROUND(الإعدادات!$B$8-H24,2),0))) | J24: =IF(H24="","",H24+I24) | K24: =IF(J24="","",J24/الإعدادات!$B$7) | L24: =IF(OR(D24="محجوب",E24="محجوب",F24="محجوب"),"قيد المراجعة",IF(J24="",IF(OR(D24="غائب",D24="بعذر"),"إعادة مطلوبة","لم تكتمل"),IF(ROUND(J24,2)>=ROUND(الإعدادات!$B$8,2),IF(I24>0,"ناجح برأفة","ناجح"),IF(ISNUMBER(F24),"راسب","إعادة مطلوبة")))) -> لم تكتمل
A25: 1003 | B25: =INDEX(الدرجات!$B$3:$B$10,MATCH($A25,الدرجات!$A$3:$A$10,0)) -> بيتر عادل | C25: =الإعدادات!$B$25 -> اللاهوت المقارن | D25: =IF(INDEX(الدرجات!$C$3:$W$10,MATCH($A25,الدرجات!$A$3:$A$10,0),19)="","",INDEX(الدرجات!$C$3:$W$10,MATCH($A25,الدرجات!$A$3:$A$10,0),19)) | E25: =IF(INDEX(الدرجات!$C$3:$W$10,MATCH($A25,الدرجات!$A$3:$A$10,0),20)="","",INDEX(الدرجات!$C$3:$W$10,MATCH($A25,الدرجات!$A$3:$A$10,0),20)) | F25: =IF(INDEX(الدرجات!$C$3:$W$10,MATCH($A25,الدرجات!$A$3:$A$10,0),21)="","",INDEX(الدرجات!$C$3:$W$10,MATCH($A25,الدرجات!$A$3:$A$10,0),21)) | G25: =IF(OR(D25="محجوب",E25="محجوب",F25="محجوب"),"",IF(ISNUMBER(F25),IF(الإعدادات!$B$6="سقف",MIN(F25,الإعدادات!$B$10),F25),IF(ISNUMBER(D25),D25,""))) | H25: =IF(OR(D25="محجوب",E25="محجوب",F25="محجوب"),"",IF(AND(ISNUMBER(G25),ISNUMBER(E25)),G25+E25,"")) | I25: =IF(H25="","",IF(H25>=الإعدادات!$B$8,0,IF(ROUND(الإعدادات!$B$8-H25,2)<=الإعدادات!$B$9,ROUND(الإعدادات!$B$8-H25,2),0))) | J25: =IF(H25="","",H25+I25) | K25: =IF(J25="","",J25/الإعدادات!$B$7) | L25: =IF(OR(D25="محجوب",E25="محجوب",F25="محجوب"),"قيد المراجعة",IF(J25="",IF(OR(D25="غائب",D25="بعذر"),"إعادة مطلوبة","لم تكتمل"),IF(ROUND(J25,2)>=ROUND(الإعدادات!$B$8,2),IF(I25>0,"ناجح برأفة","ناجح"),IF(ISNUMBER(F25),"راسب","إعادة مطلوبة")))) -> لم تكتمل
A26: 1004 | B26: =INDEX(الدرجات!$B$3:$B$10,MATCH($A26,الدرجات!$A$3:$A$10,0)) -> مارتينا ناجي | C26: =الإعدادات!$B$19 -> العقيدة المسيحية | D26: =IF(INDEX(الدرجات!$C$3:$W$10,MATCH($A26,الدرجات!$A$3:$A$10,0),1)="","",INDEX(الدرجات!$C$3:$W$10,MATCH($A26,الدرجات!$A$3:$A$10,0),1)) | E26: =IF(INDEX(الدرجات!$C$3:$W$10,MATCH($A26,الدرجات!$A$3:$A$10,0),2)="","",INDEX(الدرجات!$C$3:$W$10,MATCH($A26,الدرجات!$A$3:$A$10,0),2)) | F26: =IF(INDEX(الدرجات!$C$3:$W$10,MATCH($A26,الدرجات!$A$3:$A$10,0),3)="","",INDEX(الدرجات!$C$3:$W$10,MATCH($A26,الدرجات!$A$3:$A$10,0),3)) | G26: =IF(OR(D26="محجوب",E26="محجوب",F26="محجوب"),"",IF(ISNUMBER(F26),IF(الإعدادات!$B$6="سقف",MIN(F26,الإعدادات!$B$10),F26),IF(ISNUMBER(D26),D26,""))) | H26: =IF(OR(D26="محجوب",E26="محجوب",F26="محجوب"),"",IF(AND(ISNUMBER(G26),ISNUMBER(E26)),G26+E26,"")) | I26: =IF(H26="","",IF(H26>=الإعدادات!$B$8,0,IF(ROUND(الإعدادات!$B$8-H26,2)<=الإعدادات!$B$9,ROUND(الإعدادات!$B$8-H26,2),0))) | J26: =IF(H26="","",H26+I26) | K26: =IF(J26="","",J26/الإعدادات!$B$7) | L26: =IF(OR(D26="محجوب",E26="محجوب",F26="محجوب"),"قيد المراجعة",IF(J26="",IF(OR(D26="غائب",D26="بعذر"),"إعادة مطلوبة","لم تكتمل"),IF(ROUND(J26,2)>=ROUND(الإعدادات!$B$8,2),IF(I26>0,"ناجح برأفة","ناجح"),IF(ISNUMBER(F26),"راسب","إعادة مطلوبة")))) -> لم تكتمل
A27: 1004 | B27: =INDEX(الدرجات!$B$3:$B$10,MATCH($A27,الدرجات!$A$3:$A$10,0)) -> مارتينا ناجي | C27: =الإعدادات!$B$20 -> العهد القديم | D27: =IF(INDEX(الدرجات!$C$3:$W$10,MATCH($A27,الدرجات!$A$3:$A$10,0),4)="","",INDEX(الدرجات!$C$3:$W$10,MATCH($A27,الدرجات!$A$3:$A$10,0),4)) | E27: =IF(INDEX(الدرجات!$C$3:$W$10,MATCH($A27,الدرجات!$A$3:$A$10,0),5)="","",INDEX(الدرجات!$C$3:$W$10,MATCH($A27,الدرجات!$A$3:$A$10,0),5)) | F27: =IF(INDEX(الدرجات!$C$3:$W$10,MATCH($A27,الدرجات!$A$3:$A$10,0),6)="","",INDEX(الدرجات!$C$3:$W$10,MATCH($A27,الدرجات!$A$3:$A$10,0),6)) | G27: =IF(OR(D27="محجوب",E27="محجوب",F27="محجوب"),"",IF(ISNUMBER(F27),IF(الإعدادات!$B$6="سقف",MIN(F27,الإعدادات!$B$10),F27),IF(ISNUMBER(D27),D27,""))) | H27: =IF(OR(D27="محجوب",E27="محجوب",F27="محجوب"),"",IF(AND(ISNUMBER(G27),ISNUMBER(E27)),G27+E27,"")) | I27: =IF(H27="","",IF(H27>=الإعدادات!$B$8,0,IF(ROUND(الإعدادات!$B$8-H27,2)<=الإعدادات!$B$9,ROUND(الإعدادات!$B$8-H27,2),0))) | J27: =IF(H27="","",H27+I27) | K27: =IF(J27="","",J27/الإعدادات!$B$7) | L27: =IF(OR(D27="محجوب",E27="محجوب",F27="محجوب"),"قيد المراجعة",IF(J27="",IF(OR(D27="غائب",D27="بعذر"),"إعادة مطلوبة","لم تكتمل"),IF(ROUND(J27,2)>=ROUND(الإعدادات!$B$8,2),IF(I27>0,"ناجح برأفة","ناجح"),IF(ISNUMBER(F27),"راسب","إعادة مطلوبة")))) -> لم تكتمل
A28: 1004 | B28: =INDEX(الدرجات!$B$3:$B$10,MATCH($A28,الدرجات!$A$3:$A$10,0)) -> مارتينا ناجي | C28: =الإعدادات!$B$21 -> العهد الجديد | D28: =IF(INDEX(الدرجات!$C$3:$W$10,MATCH($A28,الدرجات!$A$3:$A$10,0),7)="","",INDEX(الدرجات!$C$3:$W$10,MATCH($A28,الدرجات!$A$3:$A$10,0),7)) | E28: =IF(INDEX(الدرجات!$C$3:$W$10,MATCH($A28,الدرجات!$A$3:$A$10,0),8)="","",INDEX(الدرجات!$C$3:$W$10,MATCH($A28,الدرجات!$A$3:$A$10,0),8)) | F28: =IF(INDEX(الدرجات!$C$3:$W$10,MATCH($A28,الدرجات!$A$3:$A$10,0),9)="","",INDEX(الدرجات!$C$3:$W$10,MATCH($A28,الدرجات!$A$3:$A$10,0),9)) | G28: =IF(OR(D28="محجوب",E28="محجوب",F28="محجوب"),"",IF(ISNUMBER(F28),IF(الإعدادات!$B$6="سقف",MIN(F28,الإعدادات!$B$10),F28),IF(ISNUMBER(D28),D28,""))) | H28: =IF(OR(D28="محجوب",E28="محجوب",F28="محجوب"),"",IF(AND(ISNUMBER(G28),ISNUMBER(E28)),G28+E28,"")) | I28: =IF(H28="","",IF(H28>=الإعدادات!$B$8,0,IF(ROUND(الإعدادات!$B$8-H28,2)<=الإعدادات!$B$9,ROUND(الإعدادات!$B$8-H28,2),0))) | J28: =IF(H28="","",H28+I28) | K28: =IF(J28="","",J28/الإعدادات!$B$7) | L28: =IF(OR(D28="محجوب",E28="محجوب",F28="محجوب"),"قيد المراجعة",IF(J28="",IF(OR(D28="غائب",D28="بعذر"),"إعادة مطلوبة","لم تكتمل"),IF(ROUND(J28,2)>=ROUND(الإعدادات!$B$8,2),IF(I28>0,"ناجح برأفة","ناجح"),IF(ISNUMBER(F28),"راسب","إعادة مطلوبة")))) -> لم تكتمل
A29: 1004 | B29: =INDEX(الدرجات!$B$3:$B$10,MATCH($A29,الدرجات!$A$3:$A$10,0)) -> مارتينا ناجي | C29: =الإعدادات!$B$22 -> الطقوس والألحان | D29: =IF(INDEX(الدرجات!$C$3:$W$10,MATCH($A29,الدرجات!$A$3:$A$10,0),10)="","",INDEX(الدرجات!$C$3:$W$10,MATCH($A29,الدرجات!$A$3:$A$10,0),10)) | E29: =IF(INDEX(الدرجات!$C$3:$W$10,MATCH($A29,الدرجات!$A$3:$A$10,0),11)="","",INDEX(الدرجات!$C$3:$W$10,MATCH($A29,الدرجات!$A$3:$A$10,0),11)) | F29: =IF(INDEX(الدرجات!$C$3:$W$10,MATCH($A29,الدرجات!$A$3:$A$10,0),12)="","",INDEX(الدرجات!$C$3:$W$10,MATCH($A29,الدرجات!$A$3:$A$10,0),12)) | G29: =IF(OR(D29="محجوب",E29="محجوب",F29="محجوب"),"",IF(ISNUMBER(F29),IF(الإعدادات!$B$6="سقف",MIN(F29,الإعدادات!$B$10),F29),IF(ISNUMBER(D29),D29,""))) | H29: =IF(OR(D29="محجوب",E29="محجوب",F29="محجوب"),"",IF(AND(ISNUMBER(G29),ISNUMBER(E29)),G29+E29,"")) | I29: =IF(H29="","",IF(H29>=الإعدادات!$B$8,0,IF(ROUND(الإعدادات!$B$8-H29,2)<=الإعدادات!$B$9,ROUND(الإعدادات!$B$8-H29,2),0))) | J29: =IF(H29="","",H29+I29) | K29: =IF(J29="","",J29/الإعدادات!$B$7) | L29: =IF(OR(D29="محجوب",E29="محجوب",F29="محجوب"),"قيد المراجعة",IF(J29="",IF(OR(D29="غائب",D29="بعذر"),"إعادة مطلوبة","لم تكتمل"),IF(ROUND(J29,2)>=ROUND(الإعدادات!$B$8,2),IF(I29>0,"ناجح برأفة","ناجح"),IF(ISNUMBER(F29),"راسب","إعادة مطلوبة")))) -> لم تكتمل
A30: 1004 | B30: =INDEX(الدرجات!$B$3:$B$10,MATCH($A30,الدرجات!$A$3:$A$10,0)) -> مارتينا ناجي | C30: =الإعدادات!$B$23 -> تاريخ الكنيسة | D30: =IF(INDEX(الدرجات!$C$3:$W$10,MATCH($A30,الدرجات!$A$3:$A$10,0),13)="","",INDEX(الدرجات!$C$3:$W$10,MATCH($A30,الدرجات!$A$3:$A$10,0),13)) | E30: =IF(INDEX(الدرجات!$C$3:$W$10,MATCH($A30,الدرجات!$A$3:$A$10,0),14)="","",INDEX(الدرجات!$C$3:$W$10,MATCH($A30,الدرجات!$A$3:$A$10,0),14)) | F30: =IF(INDEX(الدرجات!$C$3:$W$10,MATCH($A30,الدرجات!$A$3:$A$10,0),15)="","",INDEX(الدرجات!$C$3:$W$10,MATCH($A30,الدرجات!$A$3:$A$10,0),15)) | G30: =IF(OR(D30="محجوب",E30="محجوب",F30="محجوب"),"",IF(ISNUMBER(F30),IF(الإعدادات!$B$6="سقف",MIN(F30,الإعدادات!$B$10),F30),IF(ISNUMBER(D30),D30,""))) | H30: =IF(OR(D30="محجوب",E30="محجوب",F30="محجوب"),"",IF(AND(ISNUMBER(G30),ISNUMBER(E30)),G30+E30,"")) | I30: =IF(H30="","",IF(H30>=الإعدادات!$B$8,0,IF(ROUND(الإعدادات!$B$8-H30,2)<=الإعدادات!$B$9,ROUND(الإعدادات!$B$8-H30,2),0))) | J30: =IF(H30="","",H30+I30) | K30: =IF(J30="","",J30/الإعدادات!$B$7) | L30: =IF(OR(D30="محجوب",E30="محجوب",F30="محجوب"),"قيد المراجعة",IF(J30="",IF(OR(D30="غائب",D30="بعذر"),"إعادة مطلوبة","لم تكتمل"),IF(ROUND(J30,2)>=ROUND(الإعدادات!$B$8,2),IF(I30>0,"ناجح برأفة","ناجح"),IF(ISNUMBER(F30),"راسب","إعادة مطلوبة")))) -> لم تكتمل
A31: 1004 | B31: =INDEX(الدرجات!$B$3:$B$10,MATCH($A31,الدرجات!$A$3:$A$10,0)) -> مارتينا ناجي | C31: =الإعدادات!$B$24 -> الرعاية والافتقاد | D31: =IF(INDEX(الدرجات!$C$3:$W$10,MATCH($A31,الدرجات!$A$3:$A$10,0),16)="","",INDEX(الدرجات!$C$3:$W$10,MATCH($A31,الدرجات!$A$3:$A$10,0),16)) | E31: =IF(INDEX(الدرجات!$C$3:$W$10,MATCH($A31,الدرجات!$A$3:$A$10,0),17)="","",INDEX(الدرجات!$C$3:$W$10,MATCH($A31,الدرجات!$A$3:$A$10,0),17)) | F31: =IF(INDEX(الدرجات!$C$3:$W$10,MATCH($A31,الدرجات!$A$3:$A$10,0),18)="","",INDEX(الدرجات!$C$3:$W$10,MATCH($A31,الدرجات!$A$3:$A$10,0),18)) | G31: =IF(OR(D31="محجوب",E31="محجوب",F31="محجوب"),"",IF(ISNUMBER(F31),IF(الإعدادات!$B$6="سقف",MIN(F31,الإعدادات!$B$10),F31),IF(ISNUMBER(D31),D31,""))) | H31: =IF(OR(D31="محجوب",E31="محجوب",F31="محجوب"),"",IF(AND(ISNUMBER(G31),ISNUMBER(E31)),G31+E31,"")) | I31: =IF(H31="","",IF(H31>=الإعدادات!$B$8,0,IF(ROUND(الإعدادات!$B$8-H31,2)<=الإعدادات!$B$9,ROUND(الإعدادات!$B$8-H31,2),0))) | J31: =IF(H31="","",H31+I31) | K31: =IF(J31="","",J31/الإعدادات!$B$7) | L31: =IF(OR(D31="محجوب",E31="محجوب",F31="محجوب"),"قيد المراجعة",IF(J31="",IF(OR(D31="غائب",D31="بعذر"),"إعادة مطلوبة","لم تكتمل"),IF(ROUND(J31,2)>=ROUND(الإعدادات!$B$8,2),IF(I31>0,"ناجح برأفة","ناجح"),IF(ISNUMBER(F31),"راسب","إعادة مطلوبة")))) -> لم تكتمل
A32: 1004 | B32: =INDEX(الدرجات!$B$3:$B$10,MATCH($A32,الدرجات!$A$3:$A$10,0)) -> مارتينا ناجي | C32: =الإعدادات!$B$25 -> اللاهوت المقارن | D32: =IF(INDEX(الدرجات!$C$3:$W$10,MATCH($A32,الدرجات!$A$3:$A$10,0),19)="","",INDEX(الدرجات!$C$3:$W$10,MATCH($A32,الدرجات!$A$3:$A$10,0),19)) | E32: =IF(INDEX(الدرجات!$C$3:$W$10,MATCH($A32,الدرجات!$A$3:$A$10,0),20)="","",INDEX(الدرجات!$C$3:$W$10,MATCH($A32,الدرجات!$A$3:$A$10,0),20)) | F32: =IF(INDEX(الدرجات!$C$3:$W$10,MATCH($A32,الدرجات!$A$3:$A$10,0),21)="","",INDEX(الدرجات!$C$3:$W$10,MATCH($A32,الدرجات!$A$3:$A$10,0),21)) | G32: =IF(OR(D32="محجوب",E32="محجوب",F32="محجوب"),"",IF(ISNUMBER(F32),IF(الإعدادات!$B$6="سقف",MIN(F32,الإعدادات!$B$10),F32),IF(ISNUMBER(D32),D32,""))) | H32: =IF(OR(D32="محجوب",E32="محجوب",F32="محجوب"),"",IF(AND(ISNUMBER(G32),ISNUMBER(E32)),G32+E32,"")) | I32: =IF(H32="","",IF(H32>=الإعدادات!$B$8,0,IF(ROUND(الإعدادات!$B$8-H32,2)<=الإعدادات!$B$9,ROUND(الإعدادات!$B$8-H32,2),0))) | J32: =IF(H32="","",H32+I32) | K32: =IF(J32="","",J32/الإعدادات!$B$7) | L32: =IF(OR(D32="محجوب",E32="محجوب",F32="محجوب"),"قيد المراجعة",IF(J32="",IF(OR(D32="غائب",D32="بعذر"),"إعادة مطلوبة","لم تكتمل"),IF(ROUND(J32,2)>=ROUND(الإعدادات!$B$8,2),IF(I32>0,"ناجح برأفة","ناجح"),IF(ISNUMBER(F32),"راسب","إعادة مطلوبة")))) -> لم تكتمل
A33: 1005 | B33: =INDEX(الدرجات!$B$3:$B$10,MATCH($A33,الدرجات!$A$3:$A$10,0)) -> كيرلس فادي | C33: =الإعدادات!$B$19 -> العقيدة المسيحية | D33: =IF(INDEX(الدرجات!$C$3:$W$10,MATCH($A33,الدرجات!$A$3:$A$10,0),1)="","",INDEX(الدرجات!$C$3:$W$10,MATCH($A33,الدرجات!$A$3:$A$10,0),1)) | E33: =IF(INDEX(الدرجات!$C$3:$W$10,MATCH($A33,الدرجات!$A$3:$A$10,0),2)="","",INDEX(الدرجات!$C$3:$W$10,MATCH($A33,الدرجات!$A$3:$A$10,0),2)) | F33: =IF(INDEX(الدرجات!$C$3:$W$10,MATCH($A33,الدرجات!$A$3:$A$10,0),3)="","",INDEX(الدرجات!$C$3:$W$10,MATCH($A33,الدرجات!$A$3:$A$10,0),3)) | G33: =IF(OR(D33="محجوب",E33="محجوب",F33="محجوب"),"",IF(ISNUMBER(F33),IF(الإعدادات!$B$6="سقف",MIN(F33,الإعدادات!$B$10),F33),IF(ISNUMBER(D33),D33,""))) | H33: =IF(OR(D33="محجوب",E33="محجوب",F33="محجوب"),"",IF(AND(ISNUMBER(G33),ISNUMBER(E33)),G33+E33,"")) | I33: =IF(H33="","",IF(H33>=الإعدادات!$B$8,0,IF(ROUND(الإعدادات!$B$8-H33,2)<=الإعدادات!$B$9,ROUND(الإعدادات!$B$8-H33,2),0))) | J33: =IF(H33="","",H33+I33) | K33: =IF(J33="","",J33/الإعدادات!$B$7) | L33: =IF(OR(D33="محجوب",E33="محجوب",F33="محجوب"),"قيد المراجعة",IF(J33="",IF(OR(D33="غائب",D33="بعذر"),"إعادة مطلوبة","لم تكتمل"),IF(ROUND(J33,2)>=ROUND(الإعدادات!$B$8,2),IF(I33>0,"ناجح برأفة","ناجح"),IF(ISNUMBER(F33),"راسب","إعادة مطلوبة")))) -> لم تكتمل
A34: 1005 | B34: =INDEX(الدرجات!$B$3:$B$10,MATCH($A34,الدرجات!$A$3:$A$10,0)) -> كيرلس فادي | C34: =الإعدادات!$B$20 -> العهد القديم | D34: =IF(INDEX(الدرجات!$C$3:$W$10,MATCH($A34,الدرجات!$A$3:$A$10,0),4)="","",INDEX(الدرجات!$C$3:$W$10,MATCH($A34,الدرجات!$A$3:$A$10,0),4)) | E34: =IF(INDEX(الدرجات!$C$3:$W$10,MATCH($A34,الدرجات!$A$3:$A$10,0),5)="","",INDEX(الدرجات!$C$3:$W$10,MATCH($A34,الدرجات!$A$3:$A$10,0),5)) | F34: =IF(INDEX(الدرجات!$C$3:$W$10,MATCH($A34,الدرجات!$A$3:$A$10,0),6)="","",INDEX(الدرجات!$C$3:$W$10,MATCH($A34,الدرجات!$A$3:$A$10,0),6)) | G34: =IF(OR(D34="محجوب",E34="محجوب",F34="محجوب"),"",IF(ISNUMBER(F34),IF(الإعدادات!$B$6="سقف",MIN(F34,الإعدادات!$B$10),F34),IF(ISNUMBER(D34),D34,""))) | H34: =IF(OR(D34="محجوب",E34="محجوب",F34="محجوب"),"",IF(AND(ISNUMBER(G34),ISNUMBER(E34)),G34+E34,"")) | I34: =IF(H34="","",IF(H34>=الإعدادات!$B$8,0,IF(ROUND(الإعدادات!$B$8-H34,2)<=الإعدادات!$B$9,ROUND(الإعدادات!$B$8-H34,2),0))) | J34: =IF(H34="","",H34+I34) | K34: =IF(J34="","",J34/الإعدادات!$B$7) | L34: =IF(OR(D34="محجوب",E34="محجوب",F34="محجوب"),"قيد المراجعة",IF(J34="",IF(OR(D34="غائب",D34="بعذر"),"إعادة مطلوبة","لم تكتمل"),IF(ROUND(J34,2)>=ROUND(الإعدادات!$B$8,2),IF(I34>0,"ناجح برأفة","ناجح"),IF(ISNUMBER(F34),"راسب","إعادة مطلوبة")))) -> لم تكتمل
A35: 1005 | B35: =INDEX(الدرجات!$B$3:$B$10,MATCH($A35,الدرجات!$A$3:$A$10,0)) -> كيرلس فادي | C35: =الإعدادات!$B$21 -> العهد الجديد | D35: =IF(INDEX(الدرجات!$C$3:$W$10,MATCH($A35,الدرجات!$A$3:$A$10,0),7)="","",INDEX(الدرجات!$C$3:$W$10,MATCH($A35,الدرجات!$A$3:$A$10,0),7)) | E35: =IF(INDEX(الدرجات!$C$3:$W$10,MATCH($A35,الدرجات!$A$3:$A$10,0),8)="","",INDEX(الدرجات!$C$3:$W$10,MATCH($A35,الدرجات!$A$3:$A$10,0),8)) | F35: =IF(INDEX(الدرجات!$C$3:$W$10,MATCH($A35,الدرجات!$A$3:$A$10,0),9)="","",INDEX(الدرجات!$C$3:$W$10,MATCH($A35,الدرجات!$A$3:$A$10,0),9)) | G35: =IF(OR(D35="محجوب",E35="محجوب",F35="محجوب"),"",IF(ISNUMBER(F35),IF(الإعدادات!$B$6="سقف",MIN(F35,الإعدادات!$B$10),F35),IF(ISNUMBER(D35),D35,""))) | H35: =IF(OR(D35="محجوب",E35="محجوب",F35="محجوب"),"",IF(AND(ISNUMBER(G35),ISNUMBER(E35)),G35+E35,"")) | I35: =IF(H35="","",IF(H35>=الإعدادات!$B$8,0,IF(ROUND(الإعدادات!$B$8-H35,2)<=الإعدادات!$B$9,ROUND(الإعدادات!$B$8-H35,2),0))) | J35: =IF(H35="","",H35+I35) | K35: =IF(J35="","",J35/الإعدادات!$B$7) | L35: =IF(OR(D35="محجوب",E35="محجوب",F35="محجوب"),"قيد المراجعة",IF(J35="",IF(OR(D35="غائب",D35="بعذر"),"إعادة مطلوبة","لم تكتمل"),IF(ROUND(J35,2)>=ROUND(الإعدادات!$B$8,2),IF(I35>0,"ناجح برأفة","ناجح"),IF(ISNUMBER(F35),"راسب","إعادة مطلوبة")))) -> لم تكتمل
A36: 1005 | B36: =INDEX(الدرجات!$B$3:$B$10,MATCH($A36,الدرجات!$A$3:$A$10,0)) -> كيرلس فادي | C36: =الإعدادات!$B$22 -> الطقوس والألحان | D36: =IF(INDEX(الدرجات!$C$3:$W$10,MATCH($A36,الدرجات!$A$3:$A$10,0),10)="","",INDEX(الدرجات!$C$3:$W$10,MATCH($A36,الدرجات!$A$3:$A$10,0),10)) | E36: =IF(INDEX(الدرجات!$C$3:$W$10,MATCH($A36,الدرجات!$A$3:$A$10,0),11)="","",INDEX(الدرجات!$C$3:$W$10,MATCH($A36,الدرجات!$A$3:$A$10,0),11)) | F36: =IF(INDEX(الدرجات!$C$3:$W$10,MATCH($A36,الدرجات!$A$3:$A$10,0),12)="","",INDEX(الدرجات!$C$3:$W$10,MATCH($A36,الدرجات!$A$3:$A$10,0),12)) | G36: =IF(OR(D36="محجوب",E36="محجوب",F36="محجوب"),"",IF(ISNUMBER(F36),IF(الإعدادات!$B$6="سقف",MIN(F36,الإعدادات!$B$10),F36),IF(ISNUMBER(D36),D36,""))) | H36: =IF(OR(D36="محجوب",E36="محجوب",F36="محجوب"),"",IF(AND(ISNUMBER(G36),ISNUMBER(E36)),G36+E36,"")) | I36: =IF(H36="","",IF(H36>=الإعدادات!$B$8,0,IF(ROUND(الإعدادات!$B$8-H36,2)<=الإعدادات!$B$9,ROUND(الإعدادات!$B$8-H36,2),0))) | J36: =IF(H36="","",H36+I36) | K36: =IF(J36="","",J36/الإعدادات!$B$7) | L36: =IF(OR(D36="محجوب",E36="محجوب",F36="محجوب"),"قيد المراجعة",IF(J36="",IF(OR(D36="غائب",D36="بعذر"),"إعادة مطلوبة","لم تكتمل"),IF(ROUND(J36,2)>=ROUND(الإعدادات!$B$8,2),IF(I36>0,"ناجح برأفة","ناجح"),IF(ISNUMBER(F36),"راسب","إعادة مطلوبة")))) -> لم تكتمل
A37: 1005 | B37: =INDEX(الدرجات!$B$3:$B$10,MATCH($A37,الدرجات!$A$3:$A$10,0)) -> كيرلس فادي | C37: =الإعدادات!$B$23 -> تاريخ الكنيسة | D37: =IF(INDEX(الدرجات!$C$3:$W$10,MATCH($A37,الدرجات!$A$3:$A$10,0),13)="","",INDEX(الدرجات!$C$3:$W$10,MATCH($A37,الدرجات!$A$3:$A$10,0),13)) | E37: =IF(INDEX(الدرجات!$C$3:$W$10,MATCH($A37,الدرجات!$A$3:$A$10,0),14)="","",INDEX(الدرجات!$C$3:$W$10,MATCH($A37,الدرجات!$A$3:$A$10,0),14)) | F37: =IF(INDEX(الدرجات!$C$3:$W$10,MATCH($A37,الدرجات!$A$3:$A$10,0),15)="","",INDEX(الدرجات!$C$3:$W$10,MATCH($A37,الدرجات!$A$3:$A$10,0),15)) | G37: =IF(OR(D37="محجوب",E37="محجوب",F37="محجوب"),"",IF(ISNUMBER(F37),IF(الإعدادات!$B$6="سقف",MIN(F37,الإعدادات!$B$10),F37),IF(ISNUMBER(D37),D37,""))) | H37: =IF(OR(D37="محجوب",E37="محجوب",F37="محجوب"),"",IF(AND(ISNUMBER(G37),ISNUMBER(E37)),G37+E37,"")) | I37: =IF(H37="","",IF(H37>=الإعدادات!$B$8,0,IF(ROUND(الإعدادات!$B$8-H37,2)<=الإعدادات!$B$9,ROUND(الإعدادات!$B$8-H37,2),0))) | J37: =IF(H37="","",H37+I37) | K37: =IF(J37="","",J37/الإعدادات!$B$7) | L37: =IF(OR(D37="محجوب",E37="محجوب",F37="محجوب"),"قيد المراجعة",IF(J37="",IF(OR(D37="غائب",D37="بعذر"),"إعادة مطلوبة","لم تكتمل"),IF(ROUND(J37,2)>=ROUND(الإعدادات!$B$8,2),IF(I37>0,"ناجح برأفة","ناجح"),IF(ISNUMBER(F37),"راسب","إعادة مطلوبة")))) -> لم تكتمل
A38: 1005 | B38: =INDEX(الدرجات!$B$3:$B$10,MATCH($A38,الدرجات!$A$3:$A$10,0)) -> كيرلس فادي | C38: =الإعدادات!$B$24 -> الرعاية والافتقاد | D38: =IF(INDEX(الدرجات!$C$3:$W$10,MATCH($A38,الدرجات!$A$3:$A$10,0),16)="","",INDEX(الدرجات!$C$3:$W$10,MATCH($A38,الدرجات!$A$3:$A$10,0),16)) | E38: =IF(INDEX(الدرجات!$C$3:$W$10,MATCH($A38,الدرجات!$A$3:$A$10,0),17)="","",INDEX(الدرجات!$C$3:$W$10,MATCH($A38,الدرجات!$A$3:$A$10,0),17)) | F38: =IF(INDEX(الدرجات!$C$3:$W$10,MATCH($A38,الدرجات!$A$3:$A$10,0),18)="","",INDEX(الدرجات!$C$3:$W$10,MATCH($A38,الدرجات!$A$3:$A$10,0),18)) | G38: =IF(OR(D38="محجوب",E38="محجوب",F38="محجوب"),"",IF(ISNUMBER(F38),IF(الإعدادات!$B$6="سقف",MIN(F38,الإعدادات!$B$10),F38),IF(ISNUMBER(D38),D38,""))) | H38: =IF(OR(D38="محجوب",E38="محجوب",F38="محجوب"),"",IF(AND(ISNUMBER(G38),ISNUMBER(E38)),G38+E38,"")) | I38: =IF(H38="","",IF(H38>=الإعدادات!$B$8,0,IF(ROUND(الإعدادات!$B$8-H38,2)<=الإعدادات!$B$9,ROUND(الإعدادات!$B$8-H38,2),0))) | J38: =IF(H38="","",H38+I38) | K38: =IF(J38="","",J38/الإعدادات!$B$7) | L38: =IF(OR(D38="محجوب",E38="محجوب",F38="محجوب"),"قيد المراجعة",IF(J38="",IF(OR(D38="غائب",D38="بعذر"),"إعادة مطلوبة","لم تكتمل"),IF(ROUND(J38,2)>=ROUND(الإعدادات!$B$8,2),IF(I38>0,"ناجح برأفة","ناجح"),IF(ISNUMBER(F38),"راسب","إعادة مطلوبة")))) -> لم تكتمل
A39: 1005 | B39: =INDEX(الدرجات!$B$3:$B$10,MATCH($A39,الدرجات!$A$3:$A$10,0)) -> كيرلس فادي | C39: =الإعدادات!$B$25 -> اللاهوت المقارن | D39: =IF(INDEX(الدرجات!$C$3:$W$10,MATCH($A39,الدرجات!$A$3:$A$10,0),19)="","",INDEX(الدرجات!$C$3:$W$10,MATCH($A39,الدرجات!$A$3:$A$10,0),19)) | E39: =IF(INDEX(الدرجات!$C$3:$W$10,MATCH($A39,الدرجات!$A$3:$A$10,0),20)="","",INDEX(الدرجات!$C$3:$W$10,MATCH($A39,الدرجات!$A$3:$A$10,0),20)) | F39: =IF(INDEX(الدرجات!$C$3:$W$10,MATCH($A39,الدرجات!$A$3:$A$10,0),21)="","",INDEX(الدرجات!$C$3:$W$10,MATCH($A39,الدرجات!$A$3:$A$10,0),21)) | G39: =IF(OR(D39="محجوب",E39="محجوب",F39="محجوب"),"",IF(ISNUMBER(F39),IF(الإعدادات!$B$6="سقف",MIN(F39,الإعدادات!$B$10),F39),IF(ISNUMBER(D39),D39,""))) | H39: =IF(OR(D39="محجوب",E39="محجوب",F39="محجوب"),"",IF(AND(ISNUMBER(G39),ISNUMBER(E39)),G39+E39,"")) | I39: =IF(H39="","",IF(H39>=الإعدادات!$B$8,0,IF(ROUND(الإعدادات!$B$8-H39,2)<=الإعدادات!$B$9,ROUND(الإعدادات!$B$8-H39,2),0))) | J39: =IF(H39="","",H39+I39) | K39: =IF(J39="","",J39/الإعدادات!$B$7) | L39: =IF(OR(D39="محجوب",E39="محجوب",F39="محجوب"),"قيد المراجعة",IF(J39="",IF(OR(D39="غائب",D39="بعذر"),"إعادة مطلوبة","لم تكتمل"),IF(ROUND(J39,2)>=ROUND(الإعدادات!$B$8,2),IF(I39>0,"ناجح برأفة","ناجح"),IF(ISNUMBER(F39),"راسب","إعادة مطلوبة")))) -> لم تكتمل
A40: 1006 | B40: =INDEX(الدرجات!$B$3:$B$10,MATCH($A40,الدرجات!$A$3:$A$10,0)) -> إيريني صبحي | C40: =الإعدادات!$B$19 -> العقيدة المسيحية | D40: =IF(INDEX(الدرجات!$C$3:$W$10,MATCH($A40,الدرجات!$A$3:$A$10,0),1)="","",INDEX(الدرجات!$C$3:$W$10,MATCH($A40,الدرجات!$A$3:$A$10,0),1)) | E40: =IF(INDEX(الدرجات!$C$3:$W$10,MATCH($A40,الدرجات!$A$3:$A$10,0),2)="","",INDEX(الدرجات!$C$3:$W$10,MATCH($A40,الدرجات!$A$3:$A$10,0),2)) | F40: =IF(INDEX(الدرجات!$C$3:$W$10,MATCH($A40,الدرجات!$A$3:$A$10,0),3)="","",INDEX(الدرجات!$C$3:$W$10,MATCH($A40,الدرجات!$A$3:$A$10,0),3)) | G40: =IF(OR(D40="محجوب",E40="محجوب",F40="محجوب"),"",IF(ISNUMBER(F40),IF(الإعدادات!$B$6="سقف",MIN(F40,الإعدادات!$B$10),F40),IF(ISNUMBER(D40),D40,""))) | H40: =IF(OR(D40="محجوب",E40="محجوب",F40="محجوب"),"",IF(AND(ISNUMBER(G40),ISNUMBER(E40)),G40+E40,"")) | I40: =IF(H40="","",IF(H40>=الإعدادات!$B$8,0,IF(ROUND(الإعدادات!$B$8-H40,2)<=الإعدادات!$B$9,ROUND(الإعدادات!$B$8-H40,2),0))) | J40: =IF(H40="","",H40+I40) | K40: =IF(J40="","",J40/الإعدادات!$B$7) | L40: =IF(OR(D40="محجوب",E40="محجوب",F40="محجوب"),"قيد المراجعة",IF(J40="",IF(OR(D40="غائب",D40="بعذر"),"إعادة مطلوبة","لم تكتمل"),IF(ROUND(J40,2)>=ROUND(الإعدادات!$B$8,2),IF(I40>0,"ناجح برأفة","ناجح"),IF(ISNUMBER(F40),"راسب","إعادة مطلوبة")))) -> لم تكتمل
...

Sheet الإعدادات
A1: الإعدادات (تحدد قواعد الحساب في النتائج)
A2: النهاية العظمى للتحريري | B2: 70 | C2: مدخل من أمين الخدمة (مثال)
A3: النهاية العظمى للشفوي | B3: 30 | C3: مدخل من أمين الخدمة (مثال)
A4: حد النجاح (%) | B4: 60 | C4: مدخل من أمين الخدمة. هو نفسه حد اللون الأحمر
A5: سقف الرأفة (%) | B5: 5 | C5: مدخل من أمين الخدمة. تُمنح فقط إذا أوصلت للنجاح
A6: قاعدة الإعادة | B6: سقف | C6: سقف = تحل محل التحريري وسقفها حد النجاح. كاملة = بالدرجة كاملة
A7: درجة المادة الكاملة | B7: =B2+B3 -> 100 | C7: مجموع النهايتين
A8: درجة النجاح | B8: =B7*B4/100 -> 60 | C8: حد النجاح × درجة المادة
A9: الرأفة القصوى بالدرجات | B9: =B7*B5/100 -> 5 | C9: سقف الرأفة × درجة المادة
A10: سقف درجة الإعادة | B10: =B2*B4/100 -> 42 | C10: التحريري × حد النجاح (عند قاعدة «سقف»)
A12: بيانات الملف
A13: إصدار صيغة الملف | B13: kd-grades-v1 | C13: يتحقق منه الاستيراد. لا تعدله
A14: الفرقة | B14: الفرقة الأولى | C14: يجب أن تطابق الفرقة المختارة عند الاستيراد
A15: العام الدراسي | B15: 2026/2027 | C15: قيمة مثال
A17: المواد (الترتيب ثابت ويطابق أعمدة ورقة الدرجات)
A18: المعرّف | B18: اسم المادة
A19: s1 | B19: العقيدة المسيحية
A20: s2 | B20: العهد القديم
A21: s3 | B21: العهد الجديد
A22: s4 | B22: الطقوس والألحان
A23: s5 | B23: تاريخ الكنيسة
A24: s6 | B24: الرعاية والافتقاد
A25: s7 | B25: اللاهوت المقارن

Sheet تعليمات
A1: تعليمات استخدام ملف الدرجات القياسي
A3: الاستخدام
A4: 1 | B4: هذا الملف هو صيغة التصدير والاستيراد نفسها: ما يُصدَّر من التطبيق يُرفع كما هو بعد تعديله.
A5: 2 | B5: عدّل خلايا ورقة «الدرجات» فقط (الخلايا بخط أزرق). ورقة «النتائج» محسوبة ولا تُستورد.
A6: 3 | B6: القيم المقبولة في خلية الدرجة: رقم بين 0 والنهاية العظمى، أو إحدى الكلمات: غائب / بعذر / محجوب.
A7: 4 | B7: الخلية الفارغة تعني «لم تُرصد» ولا تمحو درجة موجودة في التطبيق عند الاستيراد.
A8: 5 | B8: الإعادة تخص التحريري فقط. املأ خانة «إعادة التحريري» للمخدومين الذين أعادوا الامتحان فقط.
A9: 6 | B9: «محجوب» لأمين الخدمة فقط. إن استورده خادم، تُحوَّل الخلية إلى ملاحظة لأمين الخدمة بدل الحجب.
A10: 7 | B10: قبل الحفظ في التطبيق تظهر شاشة معاينة بالأخطاء (كود غير مسجل، درجة أكبر من النهاية، تكرار).
A11: لا تفعل
A12: • | B12: لا تغيّر الصف الأول المخفي في ورقة «الدرجات» (مفاتيح الأعمدة)، ولا ترتيب الأعمدة أو أسماء الأوراق.
A13: • | B13: لا تحذف كود المخدوم أو تغيّره. الاستيراد يطابق المخدوم بالكود وليس بالاسم.
A14: الألوان (تظهر تلقائياً)
A15: أحمر | B15: درجة أقل من حد النجاح في الإعدادات
A16: رمادي | B16: غائب أو بعذر
A17: أسود | B17: درجة محجوبة (يقرّرها أمين الخدمة)
A19: مثال لصف صحيح
A20: الكود | B20: الاسم | C20: العقيدة تحريري | D20: العقيدة شفوي | E20: العقيدة إعادة
A21: 1001 | B21: مينا جرجس | C21: 58 | D21: 26
A22: مثال آخر: خانة التحريري = غائب ثم خانة الإعادة = 49 (مخدوم غاب ثم أعاد الامتحان).
A23: هذا نموذج فارغ بأسماء تجريبية. في التصدير الحقيقي تُملأ القائمة بمخدومي الفرقة.
